Workbook

Sheet final_phase2_full_costs
A1: House_ID | B1: Market | C1: Phase | D1: Tier | E1: Buy_Month | F1: Sell_Month | G1: Holding_Period | H1: Buy_Price | I1: Rehab_Cost | J1: Appreciation_Gain | K1: Uplift_Gain | L1: Sell_Price | M1: Insurance_Cost | N1: Property_Tax_Cost | O1: Maintenance_Cost | P1: HOA_Cost | Q1: Total_Holding_Cost | R1: Buy_Txn_Cost | S1: Sell_Txn_Cost | T1: Service_Fee_Buy | U1: Service_Fee_Sell | V1: Profit
A2: 1 | B2: Dallas | C2: 2 | D2: Tier 1 | E2: 13 | F2: 17 | G2: 4 | H2: 338000 | I2: 27642.992 | J2: 4447.8785 | K2: 27642.992 | L2: 397733.86 | M2: 450.66667 | N2: 2028 | O2: 240 | P2: 200 | Q2: 2918.6667 | R2: 3380 | S2: 4772.8063 | T2: 10140 | U2: 11932.016 | V2: =L2-H2 -> 59733.862
A3: 2 | B3: Dallas | C3: 2 | D3: Tier 1 | E3: 13 | F3: 17 | G3: 4 | H3: 338000 | I3: 27642.992 | J3: 4447.8785 | K3: 27642.992 | L3: 397733.86 | M3: 450.66667 | N3: 2028 | O3: 240 | P3: 200 | Q3: 2918.6667 | R3: 3380 | S3: 4772.8063 | T3: 10140 | U3: 11932.016 | V3: =L3-H3 -> 59733.862
V4: =SUM(V2:V3) -> 119467.72
A5: 3 | B5: Dallas | C5: 2 | D5: Tier 2 | E5: 13 | F5: 18 | G5: 5 | H5: 443000 | I5: 27172.734 | J5: 8199.7468 | K5: 27172.734 | L5: 505545.21 | M5: 738.33333 | N5: 3322.5 | O5: 300 | P5: 250 | Q5: 4610.8333 | R5: 4430 | S5: 6066.5426 | T5: 13290 | U5: 15166.356 | V5: =L5-H5 -> 62545.215
A6: 4 | B6: Dallas | C6: 2 | D6: Tier 2 | E6: 13 | F6: 18 | G6: 5 | H6: 443000 | I6: 27172.734 | J6: 8199.7468 | K6: 27172.734 | L6: 505545.21 | M6: 738.33333 | N6: 3322.5 | O6: 300 | P6: 250 | Q6: 4610.8333 | R6: 4430 | S6: 6066.5426 | T6: 13290 | U6: 15166.356 | V6: =L6-H6 -> 62545.215
A7: 5 | B7: Dallas | C7: 2 | D7: Tier 2 | E7: 13 | F7: 18 | G7: 5 | H7: 443000 | I7: 27172.734 | J7: 8199.7468 | K7: 27172.734 | L7: 505545.21 | M7: 738.33333 | N7: 3322.5 | O7: 300 | P7: 250 | Q7: 4610.8333 | R7: 4430 | S7: 6066.5426 | T7: 13290 | U7: 15166.356 | V7: =L7-H7 -> 62545.215
A8: 8 | B8: Dallas | C8: 2 | D8: Tier 1 | E8: 14 | F8: 18 | G8: 4 | H8: 338000 | I8: 27642.992 | J8: 4447.8785 | K8: 27642.992 | L8: 397733.86 | M8: 450.66667 | N8: 2028 | O8: 240 | P8: 200 | Q8: 2918.6667 | R8: 3380 | S8: 4772.8063 | T8: 10140 | U8: 11932.016 | V8: =L8-H8 -> 59733.862
A9: 9 | B9: Dallas | C9: 2 | D9: Tier 1 | E9: 14 | F9: 18 | G9: 4 | H9: 338000 | I9: 27642.992 | J9: 4447.8785 | K9: 27642.992 | L9: 397733.86 | M9: 450.66667 | N9: 2028 | O9: 240 | P9: 200 | Q9: 2918.6667 | R9: 3380 | S9: 4772.8063 | T9: 10140 | U9: 11932.016 | V9: =L9-H9 -> 59733.862
A10: 11 | B10: Dallas | C10: 2 | D10: Tier 1 | E10: 14 | F10: 18 | G10: 4 | H10: 338000 | I10: 27642.992 | J10: 4447.8785 | K10: 27642.992 | L10: 397733.86 | M10: 450.66667 | N10: 2028 | O10: 240 | P10: 200 | Q10: 2918.6667 | R10: 3380 | S10: 4772.8063 | T10: 10140 | U10: 11932.016 | V10: =L10-H10 -> 59733.862
A11: 22 | B11: Dallas | C11: 2 | D11: Tier 1 | E11: 15 | F11: 18 | G11: 3 | H11: 338000 | I11: 27642.992 | J11: 3330.4514 | K11: 27642.992 | L11: 396616.44 | M11: 338 | N11: 1521 | O11: 180 | P11: 150 | Q11: 2189 | R11: 3380 | S11: 4759.3972 | T11: 10140 | U11: 11898.493 | V11: =L11-H11 -> 58616.435
V12: =SUM(V5:V11) -> 425453.67
A13: 6 | B13: Dallas | C13: 2 | D13: Tier 2 | E13: 13 | F13: 19 | G13: 6 | H13: 443000 | I13: 27172.734 | J13: 9857.8199 | K13: 27172.734 | L13: 507203.29 | M13: 886 | N13: 3987 | O13: 360 | P13: 300 | Q13: 5533 | R13: 4430 | S13: 6086.4395 | T13: 13290 | U13: 15216.099 | V13: =L13-H13 -> 64203.288
A14: 7 | B14: Dallas | C14: 2 | D14: Tier 3 | E14: 13 | F14: 19 | G14: 6 | H14: 676000 | I14: 34553.74 | J14: 16693.872 | K14: 34553.74 | L14: 761801.35 | M14: 1352 | N14: 6084 | O14: 360 | P14: 300 | Q14: 8096 | R14: 6760 | S14: 9141.6162 | T14: 20280 | U14: 22854.041 | V14: =L14-H14 -> 85801.352
A15: 10 | B15: Dallas | C15: 2 | D15: Tier 1 | E15: 14 | F15: 19 | G15: 5 | H15: 338000 | I15: 27642.992 | J15: 5568.9637 | K15: 27642.992 | L15: 398854.95 | M15: 563.33333 | N15: 2535 | O15: 300 | P15: 250 | Q15: 3648.3333 | R15: 3380 | S15: 4786.2594 | T15: 10140 | U15: 11965.648 | V15: =L15-H15 -> 60854.948
A16: 14 | B16: Dallas | C16: 2 | D16: Tier 2 | E16: 14 | F16: 19 | G16: 5 | H16: 443000 | I16: 27172.734 | J16: 8199.7468 | K16: 27172.734 | L16: 505545.21 | M16: 738.33333 | N16: 3322.5 | O16: 300 | P16: 250 | Q16: 4610.8333 | R16: 4430 | S16: 6066.5426 | T16: 13290 | U16: 15166.356 | V16: =L16-H16 -> 62545.215
A17: 16 | B17: Dallas | C17: 2 | D17: Tier 2 | E17: 14 | F17: 19 | G17: 5 | H17: 443000 | I17: 27172.734 | J17: 8199.7468 | K17: 27172.734 | L17: 505545.21 | M17: 738.33333 | N17: 3322.5 | O17: 300 | P17: 250 | Q17: 4610.8333 | R17: 4430 | S17: 6066.5426 | T17: 13290 | U17: 15166.356 | V17: =L17-H17 -> 62545.215
A18: 21 | B18: Dallas | C18: 2 | D18: Tier 1 | E18: 15 | F18: 19 | G18: 4 | H18: 338000 | I18: 27642.992 | J18: 4447.8785 | K18: 27642.992 | L18: 397733.86 | M18: 450.66667 | N18: 2028 | O18: 240 | P18: 200 | Q18: 2918.6667 | R18: 3380 | S18: 4772.8063 | T18: 10140 | U18: 11932.016 | V18: =L18-H18 -> 59733.862
A19: 25 | B19: Dallas | C19: 2 | D19: Tier 2 | E19: 15 | F19: 19 | G19: 4 | H19: 443000 | I19: 27172.734 | J19: 6547.7445 | K19: 27172.734 | L19: 503893.21 | M19: 590.66667 | N19: 2658 | O19: 240 | P19: 200 | Q19: 3688.6667 | R19: 4430 | S19: 6046.7186 | T19: 13290 | U19: 15116.796 | V19: =L19-H19 -> 60893.213
A20: 26 | B20: Dallas | C20: 2 | D20: Tier 2 | E20: 15 | F20: 19 | G20: 4 | H20: 443000 | I20: 27172.734 | J20: 6547.7445 | K20: 27172.734 | L20: 503893.21 | M20: 590.66667 | N20: 2658 | O20: 240 | P20: 200 | Q20: 3688.6667 | R20: 4430 | S20: 6046.7186 | T20: 13290 | U20: 15116.796 | V20: =L20-H20 -> 60893.213
A21: 28 | B21: Dallas | C21: 2 | D21: Tier 2 | E21: 15 | F21: 19 | G21: 4 | H21: 443000 | I21: 27172.734 | J21: 6547.7445 | K21: 27172.734 | L21: 503893.21 | M21: 590.66667 | N21: 2658 | O21: 240 | P21: 200 | Q21: 3688.6667 | R21: 4430 | S21: 6046.7186 | T21: 13290 | U21: 15116.796 | V21: =L21-H21 -> 60893.213
A22: 31 | B22: Dallas | C22: 2 | D22: Tier 1 | E22: 16 | F22: 19 | G22: 3 | H22: 338000 | I22: 27642.992 | J22: 3330.4514 | K22: 27642.992 | L22: 396616.44 | M22: 338 | N22: 1521 | O22: 180 | P22: 150 | Q22: 2189 | R22: 3380 | S22: 4759.3972 | T22: 10140 | U22: 11898.493 | V22: =L22-H22 -> 58616.435
A23: 33 | B23: Dallas | C23: 2 | D23: Tier 1 | E23: 16 | F23: 19 | G23: 3 | H23: 338000 | I23: 27642.992 | J23: 3330.4514 | K23: 27642.992 | L23: 396616.44 | M23: 338 | N23: 1521 | O23: 180 | P23: 150 | Q23: 2189 | R23: 3380 | S23: 4759.3972 | T23: 10140 | U23: 11898.493 | V23: =L23-H23 -> 58616.435
A24: 34 | B24: Dallas | C24: 2 | D24: Tier 1 | E24: 16 | F24: 19 | G24: 3 | H24: 338000 | I24: 27642.992 | J24: 3330.4514 | K24: 27642.992 | L24: 396616.44 | M24: 338 | N24: 1521 | O24: 180 | P24: 150 | Q24: 2189 | R24: 3380 | S24: 4759.3972 | T24: 10140 | U24: 11898.493 | V24: =L24-H24 -> 58616.435
V25: =SUM(V13:V24) -> 754212.82
A26: 12 | B26: Dallas | C26: 2 | D26: Tier 2 | E26: 14 | F26: 20 | G26: 6 | H26: 443000 | I26: 27172.734 | J26: 9857.8199 | K26: 27172.734 | L26: 507203.29 | M26: 886 | N26: 3987 | O26: 360 | P26: 300 | Q26: 5533 | R26: 4430 | S26: 6086.4395 | T26: 13290 | U26: 15216.099 | V26: =L26-H26 -> 64203.288
A27: 13 | B27: Dallas | C27: 2 | D27: Tier 2 | E27: 14 | F27: 20 | G27: 6 | H27: 443000 | I27: 27172.734 | J27: 9857.8199 | K27: 27172.734 | L27: 507203.29 | M27: 886 | N27: 3987 | O27: 360 | P27: 300 | Q27: 5533 | R27: 4430 | S27: 6086.4395 | T27: 13290 | U27: 15216.099 | V27: =L27-H27 -> 64203.288
A28: 15 | B28: Dallas | C28: 2 | D28: Tier 2 | E28: 14 | F28: 20 | G28: 6 | H28: 443000 | I28: 27172.734 | J28: 9857.8199 | K28: 27172.734 | L28: 507203.29 | M28: 886 | N28: 3987 | O28: 360 | P28: 300 | Q28: 5533 | R28: 4430 | S28: 6086.4395 | T28: 13290 | U28: 15216.099 | V28: =L28-H28 -> 64203.288
A29: 17 | B29: Dallas | C29: 2 | D29: Tier 3 | E29: 14 | F29: 20 | G29: 6 | H29: 676000 | I29: 34553.74 | J29: 16693.872 | K29: 34553.74 | L29: 761801.35 | M29: 1352 | N29: 6084 | O29: 360 | P29: 300 | Q29: 8096 | R29: 6760 | S29: 9141.6162 | T29: 20280 | U29: 22854.041 | V29: =L29-H29 -> 85801.352
A30: 18 | B30: Dallas | C30: 2 | D30: Tier 1 | E30: 15 | F30: 20 | G30: 5 | H30: 338000 | I30: 27642.992 | J30: 5568.9637 | K30: 27642.992 | L30: 398854.95 | M30: 563.33333 | N30: 2535 | O30: 300 | P30: 250 | Q30: 3648.3333 | R30: 3380 | S30: 4786.2594 | T30: 10140 | U30: 11965.648 | V30: =L30-H30 -> 60854.948
A31: 19 | B31: Dallas | C31: 2 | D31: Tier 1 | E31: 15 | F31: 20 | G31: 5 | H31: 338000 | I31: 27642.992 | J31: 5568.9637 | K31: 27642.992 | L31: 398854.95 | M31: 563.33333 | N31: 2535 | O31: 300 | P31: 250 | Q31: 3648.3333 | R31: 3380 | S31: 4786.2594 | T31: 10140 | U31: 11965.648 | V31: =L31-H31 -> 60854.948
A32: 20 | B32: Dallas | C32: 2 | D32: Tier 1 | E32: 15 | F32: 20 | G32: 5 | H32: 338000 | I32: 27642.992 | J32: 5568.9637 | K32: 27642.992 | L32: 398854.95 | M32: 563.33333 | N32: 2535 | O32: 300 | P32: 250 | Q32: 3648.3333 | R32: 3380 | S32: 4786.2594 | T32: 10140 | U32: 11965.648 | V32: =L32-H32 -> 60854.948
A33: 30 | B33: Dallas | C33: 2 | D33: Tier 3 | E33: 15 | F33: 20 | G33: 5 | H33: 676000 | I33: 34553.74 | J33: 13883.202 | K33: 34553.74 | L33: 758990.68 | M33: 1126.6667 | N33: 5070 | O33: 300 | P33: 250 | Q33: 6746.6667 | R33: 6760 | S33: 9107.8882 | T33: 20280 | U33: 22769.72 | V33: =L33-H33 -> 82990.682
A34: 38 | B34: Dallas | C34: 2 | D34: Tier 2 | E34: 16 | F34: 20 | G34: 4 | H34: 443000 | I34: 27172.734 | J34: 6547.7445 | K34: 27172.734 | L34: 503893.21 | M34: 590.66667 | N34: 2658 | O34: 240 | P34: 200 | Q34: 3688.6667 | R34: 4430 | S34: 6046.7186 | T34: 13290 | U34: 15116.796 | V34: =L34-H34 -> 60893.213
A35: 42 | B35: Dallas | C35: 2 | D35: Tier 2 | E35: 16 | F35: 20 | G35: 4 | H35: 443000 | I35: 27172.734 | J35: 6547.7445 | K35: 27172.734 | L35: 503893.21 | M35: 590.66667 | N35: 2658 | O35: 240 | P35: 200 | Q35: 3688.6667 | R35: 4430 | S35: 6046.7186 | T35: 13290 | U35: 15116.796 | V35: =L35-H35 -> 60893.213
V36: =SUM(V26:V35) -> 665753.17
A37: 23 | B37: Dallas | C37: 2 | D37: Tier 2 | E37: 15 | F37: 21 | G37: 6 | H37: 443000 | I37: 27172.734 | J37: 9857.8199 | K37: 27172.734 | L37: 507203.29 | M37: 886 | N37: 3987 | O37: 360 | P37: 300 | Q37: 5533 | R37: 4430 | S37: 6086.4395 | T37: 13290 | U37: 15216.099 | V37: =L37-H37 -> 64203.288
A38: 24 | B38: Dallas | C38: 2 | D38: Tier 2 | E38: 15 | F38: 21 | G38: 6 | H38: 443000 | I38: 27172.734 | J38: 9857.8199 | K38: 27172.734 | L38: 507203.29 | M38: 886 | N38: 3987 | O38: 360 | P38: 300 | Q38: 5533 | R38: 4430 | S38: 6086.4395 | T38: 13290 | U38: 15216.099 | V38: =L38-H38 -> 64203.288
A39: 27 | B39: Dallas | C39: 2 | D39: Tier 2 | E39: 15 | F39: 21 | G39: 6 | H39: 443000 | I39: 27172.734 | J39: 9857.8199 | K39: 27172.734 | L39: 507203.29 | M39: 886 | N39: 3987 | O39: 360 | P39: 300 | Q39: 5533 | R39: 4430 | S39: 6086.4395 | T39: 13290 | U39: 15216.099 | V39: =L39-H39 -> 64203.288
A40: 32 | B40: Dallas | C40: 2 | D40: Tier 1 | E40: 16 | F40: 21 | G40: 5 | H40: 338000 | I40: 27642.992 | J40: 5568.9637 | K40: 27642.992 | L40: 398854.95 | M40: 563.33333 | N40: 2535 | O40: 300 | P40: 250 | Q40: 3648.3333 | R40: 3380 | S40: 4786.2594 | T40: 10140 | U40: 11965.648 | V40: =L40-H40 -> 60854.948
...

Sheet Assumptions
A1: Parameter | B1: Value | C1: Notes
A2: General
A3: Start_Year | B3: 2025 | C3: Base year for model
A4: Initial_Cash | B4: 500000000 | C4: Client capital available ($)
A5: Homes & Unit Economics
A6: Homes_Y1 | B6: 300 | C6: Number of homes bought & sold in Year 1
A7: Subscription Model | G7: =400*#REF!-B4 -> #REF!
A8: Sub_Start_Subscribers_Y1 | B8: 3000 | C8: Active subscribers in Year 1
A9: Sub_Monthly_Fee | B9: 25 | C9: Subscription price per month ($)
A10: Sub_Annual_Growth_Rate | B10: 1.5 | C10: YoY growth in subscribers (multiplier)
A11: Sub_Churn_Rate | B11: 0.1 | C11: Annual churn (for refinement)
A12: Operating Expenses
A13: Tax & Other
A14: Tax_Rate | B14: 0.21 | C14: Corporate tax rate (if applied later)
A15: office_dallas
A16: monthly rent | B16: =(E60+E61)/12 -> 6476 | C16: =B16*12 -> 77712
A17: Miscellaneous Expenses | B17: =1000 -> 1000 | C17: 4000 | D17: PACKERS AND MOVERS
C24: salary
A28: Role | B28: Count | C28: Salary (Annual) | D28: Monthly Cost (per person) | E28: Monthly Total Cost | F28: Notes
A29: Customer Support Reps | B29: 3 | C29: 50000 | D29: 12500 | E29: 37500 | F29: Handles all 3k subs
A30: Seller Advisors | B30: 2 | C30: 70000 | D30: 11666 | E30: 23332 | F30: Guides sellers
A31: Field Ops (Inspectors/Coordinators) | B31: 2 | C31: 60000 | D31: 10000 | E31: 20000 | F31: On-site coordination
A32: Marketing Specialist | B32: 2 | C32: 80000 | D32: 13333 | E32: 26666 | F32: Executes marketing
A33: Data/Valuation Analyst | B33: 1 | C33: 95000 | D33: 7916 | E33: 7916 | F33: Runs valuation models
A34: Product/Tech Lead | B34: 1 | C34: 120000 | D34: 10000 | E34: 10000 | F34: Single technical owner
A35: Partnerships Manager | B35: 1 | C35: 85000 | D35: 7083 | E35: 7083 | F35: Vendor + local onboarding
A36: Dallas General Manager | B36: 1 | C36: 150000 | D36: 12500 | E36: 12500 | F36: Runs entire metro
D37: TOTAL SALARY | E37: =SUM(E29:E36) -> 144997
C38: office cost
B41: Rate ($/sq ft/year) | C41: Monthly Rent (800 sq ft)
A42: Downtown Dallas | B42: 29 | C42: $1,933/month
A43: Uptown Dallas | B43: 44 | C43: $2,933/
A49: Expense Type | B49: Monthly Cost
A50: Electricity | B50: 200
A51: Internet | B51: 120
A52: Cleaning | B52: 150
A53: Water/Trash | B53: 50
A54: Office Supplies | B54: 75
A55: Insurance | B55: 60
A56: Furniture amortized | B56: 150
...

Sheet calculation_sheet
A1: Month | B1: Houses_Bought | C1: Houses_Sold | D1: Cumm_houses_bought | E1: Cumm_houses_sold | F1: Inventory | G1: Total_Buy_Price | H1: Total_Rehab_Cost | I1: Total_Buy_Txn_Cost | J1: Total_Holding_Cost | K1: Total_Sell_Txn_Cost | L1: Total_Service_Fees | M1: Total_Sale_Revenue | N1: Net_Cashflow | O1: Cumulative_Net_Cashflow
A2: 1 | B2: 10 | C2: 0 | D2: =SUM($B$2:B2) -> 10 | E2: =SUM($C$2:C2) -> 0 | F2: =E2-D2 -> -10 | G2: 4243000 | H2: 274860 | I2: =G2*0.01 -> 42430 | J2: 8878.8333 | K2: =M2*0.01 -> 0 | L2: =0.04*(G2+M2) -> 169720 | M2: 0 | N2: =(M2+L2)-(G2+H2+I2+J2+K2) -> -4399448.8 | O2: =SUM($N$2:N2) -> -4399448.8
A3: 2 | B3: 15 | C3: 0 | D3: =SUM($B$2:B3) -> 25 | E3: =SUM($C$2:C3) -> 0 | F3: =E3-D3 -> -25 | G3: 6586000 | H3: 415440 | I3: =G3*0.01 -> 65860 | J3: 22603.167 | K3: =M3*0.01 -> 0 | L3: =0.04*(G3+M3) -> 263440 | M3: 0 | N3: =(M3+L3)-(G3+H3+I3+J3+K3) -> -6826463.2 | O3: =SUM($N$2:N3) -> -11225912
A4: 3 | B4: 20 | C4: 0 | D4: =SUM($B$2:B4) -> 45 | E4: =SUM($C$2:C4) -> 0 | F4: =E4-D4 -> -45 | G4: 8824000 | H4: 556480 | I4: =G4*0.01 -> 88240 | J4: 40980.5 | K4: =M4*0.01 -> 0 | L4: =0.04*(G4+M4) -> 352960 | M4: 0 | N4: =(M4+L4)-(G4+H4+I4+J4+K4) -> -9156740.5 | O4: =SUM($N$2:N4) -> -20382652
A5: 4 | B5: 25 | C5: 0 | D5: =SUM($B$2:B5) -> 70 | E5: =SUM($C$2:C5) -> 0 | F5: =E5-D5 -> -70 | G5: 11062000 | H5: 697520 | I5: =G5*0.01 -> 110620 | J5: 64010.833 | K5: =M5*0.01 -> 0 | L5: =0.04*(G5+M5) -> 442480 | M5: 0 | N5: =(M5+L5)-(G5+H5+I5+J5+K5) -> -11491671 | O5: =SUM($N$2:N5) -> -31874323
A6: 5 | B6: 35 | C6: 2 | D6: =SUM($B$2:B6) -> 105 | E6: =SUM($C$2:C6) -> 2 | F6: =E6-D6 -> -103 | G6: 15410000 | H6: 971920 | I6: =G6*0.01 -> 154100 | J6: 94653.167 | K6: =M6*0.01 -> 7930.5576 | L6: =0.04*(G6+M6) -> 648122.23 | M6: 793055.76 | N6: =(M6+L6)-(G6+H6+I6+J6+K6) -> -15197426 | O6: =SUM($N$2:N6) -> -47071749
A7: 6 | B7: 40 | C7: 11 | D7: =SUM($B$2:B7) -> 145 | E7: =SUM($C$2:C7) -> 13 | F7: =E7-D7 -> -132 | G7: 17648000 | H7: 1112960 | I7: =G7*0.01 -> 176480 | J7: 122611.5 | K7: =M7*0.01 -> 47931.415 | L7: =0.04*(G7+M7) -> 897645.66 | M7: 4793141.5 | N7: =(M7+L7)-(G7+H7+I7+J7+K7) -> -13417196 | O7: =SUM($N$2:N7) -> -60488945
A8: 7 | B8: 40 | C8: 16 | D8: =SUM($B$2:B8) -> 185 | E8: =SUM($C$2:C8) -> 29 | F8: =E8-D8 -> -156 | G8: 17648000 | H8: 1112960 | I8: =G8*0.01 -> 176480 | J8: 145724.33 | K8: =M8*0.01 -> 74575.097 | L8: =0.04*(G8+M8) -> 1004220.4 | M8: 7457509.7 | N8: =(M8+L8)-(G8+H8+I8+J8+K8) -> -10696009 | O8: =SUM($N$2:N8) -> -71184954
A9: 8 | B9: 35 | C9: 27 | D9: =SUM($B$2:B9) -> 220 | E9: =SUM($C$2:C9) -> 56 | F9: =E9-D9 -> -164 | G9: 15410000 | H9: 971920 | I9: =G9*0.01 -> 154100 | J9: 152909.17 | K9: =M9*0.01 -> 137044.95 | L9: =0.04*(G9+M9) -> 1164579.8 | M9: 13704495 | N9: =(M9+L9)-(G9+H9+I9+J9+K9) -> -1956899.8 | O9: =SUM($N$2:N9) -> -73141854
A10: 9 | B10: 30 | C10: 27 | D10: =SUM($B$2:B10) -> 250 | E10: =SUM($C$2:C10) -> 83 | F10: =E10-D10 -> -167 | G10: 13067000 | H10: 831340 | I10: =G10*0.01 -> 130670 | J10: 156530 | K10: =M10*0.01 -> 129322.53 | L10: =0.04*(G10+M10) -> 1039970.1 | M10: 12932253 | N10: =(M10+L10)-(G10+H10+I10+J10+K10) -> -342639.68 | O10: =SUM($N$2:N10) -> -73484494
A11: 10 | B11: 25 | C11: 30 | D11: =SUM($B$2:B11) -> 275 | E11: =SUM($C$2:C11) -> 113 | F11: =E11-D11 -> -162 | G11: 11062000 | H11: 697520 | I11: =G11*0.01 -> 110620 | J11: 153501.33 | K11: =M11*0.01 -> 142765.59 | L11: =0.04*(G11+M11) -> 1013542.3 | M11: 14276559 | N11: =(M11+L11)-(G11+H11+I11+J11+K11) -> 3123694 | O11: =SUM($N$2:N11) -> -70360800
A12: 11 | B12: 15 | C12: 48 | D12: =SUM($B$2:B12) -> 290 | E12: =SUM($C$2:C12) -> 161 | F12: =E12-D12 -> -129 | G12: 6586000 | H12: 415440 | I12: =G12*0.01 -> 65860 | J12: 123948 | K12: =M12*0.01 -> 237140.37 | L12: =0.04*(G12+M12) -> 1212001.5 | M12: 23714037 | N12: =(M12+L12)-(G12+H12+I12+J12+K12) -> 17497650 | O12: =SUM($N$2:N12) -> -52863150
A13: 12 | B13: 10 | C13: 25 | D13: =SUM($B$2:B13) -> 300 | E13: =SUM($C$2:C13) -> 186 | F13: =E13-D13 -> -114 | G13: 4243000 | H13: 274860 | I13: =G13*0.01 -> 42430 | J13: 108557.17 | K13: =M13*0.01 -> 133931.8 | L13: =0.04*(G13+M13) -> 705447.22 | M13: 13393180 | N13: =(M13+L13)-(G13+H13+I13+J13+K13) -> 9295848.6 | O13: =SUM($N$2:N13) -> -43567301
A14: 13 | B14: 7 | C14: 30 | D14: =SUM($B$2:B14) -> 307 | E14: =SUM($C$2:C14) -> 216 | F14: =E14-D14 -> -91 | G14: 3124000 | H14: 198530.66 | I14: =G14*0.01 -> 31240 | J14: 86366.5 | K14: =M14*0.01 -> 158136.39 | L14: =0.0425*(G14+M14) -> 804849.66 | M14: 15813639 | N14: =(M14+L14)-(G14+H14+I14+J14+K14) -> 13020215 | O14: =SUM($N$2:N14) -> -30547086
A15: 14 | B15: 10 | C15: 24 | D15: =SUM($B$2:B15) -> 317 | E15: =SUM($C$2:C15) -> 240 | F15: =E15-D15 -> -77 | G15: 4243000 | H15: 280989.38 | I15: =G15*0.01 -> 42430 | J15: 73756.833 | K15: =M15*0.01 -> 118164.8 | L15: =0.0425*(G15+M15) -> 682527.89 | M15: 11816480 | N15: =(M15+L15)-(G15+H15+I15+J15+K15) -> 7740666.6 | O15: =SUM($N$2:N15) -> -22806419
A16: 15 | B16: 13 | C16: 30 | D16: =SUM($B$2:B16) -> 330 | E16: =SUM($C$2:C16) -> 270 | F16: =E16-D16 -> -60 | G16: 5700000 | H16: 370358.84 | I16: =G16*0.01 -> 57000 | J16: 57376 | K16: =M16*0.01 -> 155728.59 | L16: =0.0425*(G16+M16) -> 904096.52 | M16: 15572859 | N16: =(M16+L16)-(G16+H16+I16+J16+K16) -> 10136492 | O16: =SUM($N$2:N16) -> -12669927
A17: 16 | B17: 29 | C17: 14 | D17: =SUM($B$2:B17) -> 359 | E17: =SUM($C$2:C17) -> 284 | F17: =E17-D17 -> -75 | G17: 12085000 | H17: 869701.04 | I17: =G17*0.01 -> 120850 | J17: 66005.333 | K17: =M17*0.01 -> 78796.847 | L17: =0.0425*(G17+M17) -> 848499.1 | M17: 7879684.7 | N17: =(M17+L17)-(G17+H17+I17+J17+K17) -> -4492169.4 | O17: =SUM($N$2:N17) -> -17162096
A18: 17 | B18: 35 | C18: 14 | D18: =SUM($B$2:B18) -> 394 | E18: =SUM($C$2:C18) -> 298 | F18: =E18-D18 -> -96 | G18: 14533000 | H18: 1033678 | I18: =G18*0.01 -> 145330 | J18: 81214.5 | K18: =M18*0.01 -> 70489.75 | L18: =0.0425*(G18+M18) -> 917233.94 | M18: 7048975 | N18: =(M18+L18)-(G18+H18+I18+J18+K18) -> -7897503.3 | O18: =SUM($N$2:N18) -> -25059600
A19: 18 | B19: 51 | C19: 11 | D19: =SUM($B$2:B19) -> 445 | E19: =SUM($C$2:C19) -> 309 | F19: =E19-D19 -> -136 | G19: 21018000 | H19: 1534920.2 | I19: =G19*0.01 -> 210180 | J19: 110114.33 | K19: =M19*0.01 -> 56418.992 | L19: =0.0425*(G19+M19) -> 1133045.7 | M19: 5641899.2 | N19: =(M19+L19)-(G19+H19+I19+J19+K19) -> -16154689 | O19: =SUM($N$2:N19) -> -41214288
A20: 19 | B20: 54 | C20: 12 | D20: =SUM($B$2:B20) -> 499 | E20: =SUM($C$2:C20) -> 321 | F20: =E20-D20 -> -178 | G20: 22358000 | H20: 1635620.2 | I20: =G20*0.01 -> 223580 | J20: 140768.33 | K20: =M20*0.01 -> 57782.128 | L20: =0.0425*(G20+M20) -> 1195789 | M20: 5778212.8 | N20: =(M20+L20)-(G20+H20+I20+J20+K20) -> -17441749 | O20: =SUM($N$2:N20) -> -58656037
A21: 20 | B21: 53 | C21: 10 | D21: =SUM($B$2:B21) -> 552 | E21: =SUM($C$2:C21) -> 331 | F21: =E21-D21 -> -221 | G21: 21473000 | H21: 1612478 | I21: =G21*0.01 -> 214730 | J21: 170154.5 | K21: =M21*0.01 -> 52467.532 | L21: =0.0425*(G21+M21) -> 1135589.5 | M21: 5246753.2 | N21: =(M21+L21)-(G21+H21+I21+J21+K21) -> -17140487 | O21: =SUM($N$2:N21) -> -75796524
A22: 21 | B22: 50 | C22: 25 | D22: =SUM($B$2:B22) -> 602 | E22: =SUM($C$2:C22) -> 356 | F22: =E22-D22 -> -246 | G22: 20249000 | H22: 1530489.5 | I22: =G22*0.01 -> 202490 | J22: 187561.5 | K22: =M22*0.01 -> 110545.59 | L22: =0.0425*(G22+M22) -> 1330401.3 | M22: 11054559 | N22: =(M22+L22)-(G22+H22+I22+J22+K22) -> -9895125.9 | O22: =SUM($N$2:N22) -> -85691650
A23: 22 | B23: 34 | C23: 33 | D23: =SUM($B$2:B23) -> 636 | E23: =SUM($C$2:C23) -> 389 | F23: =E23-D23 -> -247 | G23: 13864000 | H23: 1031147.3 | I23: =G23*0.01 -> 138640 | J23: 185716.5 | K23: =M23*0.01 -> 160260.25 | L23: =0.0425*(G23+M23) -> 1270326 | M23: 16026025 | N23: =(M23+L23)-(G23+H23+I23+J23+K23) -> 1916586.5 | O23: =SUM($N$2:N23) -> -83775064
A24: 23 | B24: 25 | C24: 57 | D24: =SUM($B$2:B24) -> 661 | E24: =SUM($C$2:C24) -> 446 | F24: =E24-D24 -> -215 | G24: 9843000 | H24: 759089.38 | I24: =G24*0.01 -> 98430 | J24: 160155.67 | K24: =M24*0.01 -> 265074.69 | L24: =0.0425*(G24+M24) -> 1544894.9 | M24: 26507469 | N24: =(M24+L24)-(G24+H24+I24+J24+K24) -> 16926614 | O24: =SUM($N$2:N24) -> -66848449
A25: 24 | B25: 19 | C25: 34 | D25: =SUM($B$2:B25) -> 680 | E25: =SUM($C$2:C25) -> 480 | F25: =E25-D25 -> -200 | G25: 7609000 | H25: 581330.66 | I25: =G25*0.01 -> 76090 | J25: 147690.5 | K25: =M25*0.01 -> 161075.81 | L25: =0.0425*(G25+M25) -> 1007954.7 | M25: 16107581 | N25: =(M25+L25)-(G25+H25+I25+J25+K25) -> 8540348.6 | O25: =SUM($N$2:N25) -> -58308101
... A34: 33 | B34: 0 | C34: 1 | D34: =SUM($B$2:B34) -> 680 | E34: =SUM($C$2:C34) -> 680 | F34: =E34-D34 -> 0 | G34: 0 | H34: 0 | I34: =G34*0.01 -> 0 | J34: 0 | K34: =M34*0.01 -> 7244.0704 | L34: =0.0425*(G34+M34) -> 30787.299 | M34: 724407.04 | N34: =(M34+L34)-(G34+H34+I34+J34+K34) -> 747950.27 | O34: =SUM($N$2:N34) -> 41163990

Sheet operation_exp
A1: Marketing | B1: Office | C1: Salary | D1: tech_maintain | E1: SubSCRIPTION_revenue | F1: legal_expense | G1: Miscexp | H1: Total_expense | I1: Final_Net_Cashflow | J1: Cumulative_Final_Net_Cashflow
A2: 153000 | B2: =Assumptions!B16 -> 6476 | C2: 144997 | D2: =48000/12 -> 4000 | E2: =Assumptions!E142 -> 400 | F2: =Assumptions!$C$138/12 -> 9400 | G2: 20000 | H2: =B2+D2+F2-E2+G2 -> 39476 | I2: =calculation_sheet!N2-operation_exp!H2 -> -4438924.8 | J2: =I2-Assumptions!B110 -> -4588924.8
A3: 153000 | B3: 6476 | C3: 144997 | D3: =48000/12 -> 4000 | E3: =Assumptions!E143 -> 900 | F3: =Assumptions!$C$138/12 -> 9400 | G3: 20000 | H3: =B3+D3+F3-E3+G3+Balance_Sheet!E2 -> 340973 | I3: =calculation_sheet!N3-operation_exp!H3 -> -7167436.2 | J3: =J2+I3 -> -11756361
A4: 153000 | B4: 6476 | C4: 144997 | D4: =48000/12 -> 4000 | E4: =Assumptions!E144 -> 1460 | F4: =Assumptions!$C$138/12 -> 9400 | G4: 20000 | H4: =B4+D4+F4-E4+G4+Balance_Sheet!E3 -> 340413 | I4: =calculation_sheet!N4-operation_exp!H4 -> -9497153.5 | J4: =J3+I4 -> -21253514
A5: 153000 | B5: 6476 | C5: 144997 | D5: =48000/12 -> 4000 | E5: =Assumptions!E145 -> 2220 | F5: =Assumptions!$C$138/12 -> 9400 | G5: 35000 | H5: =B5+D5+F5-E5+G5+Balance_Sheet!E4 -> 354653 | I5: =calculation_sheet!N5-operation_exp!H5 -> -11846324 | J5: =J4+I5 -> -33099838
A6: 153000 | B6: 6476 | C6: 144997 | D6: =48000/12 -> 4000 | E6: =Assumptions!E146 -> 3140 | F6: =Assumptions!$C$138/12 -> 9400 | G6: 35000 | H6: =B6+D6+F6-E6+G6+Balance_Sheet!E5 -> 353733 | I6: =calculation_sheet!N6-operation_exp!H6 -> -15551159 | J6: =J5+I6 -> -48650997
A7: 153000 | B7: 6476 | C7: 144997 | D7: =48000/12 -> 4000 | E7: =Assumptions!E147 -> 4120 | F7: =Assumptions!$C$138/12 -> 9400 | G7: 35000 | H7: =B7+D7+F7-E7+G7+Balance_Sheet!E6 -> 352753 | I7: =calculation_sheet!N7-operation_exp!H7 -> -13769949 | J7: =J6+I7 -> -62420946
A8: 153000 | B8: 6476 | C8: 144997 | D8: =48000/12 -> 4000 | E8: =Assumptions!E148 -> 5060 | F8: =Assumptions!$C$138/12 -> 9400 | G8: 35000 | H8: =B8+D8+F8-E8+G8+Balance_Sheet!E7 -> 351813 | I8: =calculation_sheet!N8-operation_exp!H8 -> -11047822 | J8: =J7+I8 -> -73468768
A9: 153000 | B9: 6476 | C9: 144997 | D9: =48000/12 -> 4000 | E9: =Assumptions!E149 -> 5900 | F9: =Assumptions!$C$138/12 -> 9400 | G9: 50000 | H9: =B9+D9+F9-E9+G9+Balance_Sheet!E8 -> 365973 | I9: =calculation_sheet!N9-operation_exp!H9 -> -2322872.8 | J9: =J8+I9 -> -75791641
A10: 153000 | B10: 6476 | C10: 144997 | D10: =48000/12 -> 4000 | E10: =Assumptions!E150 -> 6600 | F10: =Assumptions!$C$138/12 -> 9400 | G10: 50000 | H10: =B10+D10+F10-E10+G10+Balance_Sheet!E9 -> 365273 | I10: =calculation_sheet!N10-operation_exp!H10 -> -707912.68 | J10: =J9+I10 -> -76499554
A11: 153000 | B11: 6476 | C11: 144997 | D11: =48000/12 -> 4000 | E11: =Assumptions!E151 -> 7240 | F11: =Assumptions!$C$138/12 -> 9400 | G11: 50000 | H11: =B11+D11+F11-E11+G11+Balance_Sheet!E10 -> 364633 | I11: =calculation_sheet!N11-operation_exp!H11 -> 2759061 | J11: =J10+I11 -> -73740493
A12: 153000 | B12: 6476 | C12: 144997 | D12: =48000/12 -> 4000 | E12: =Assumptions!E152 -> 7540 | F12: =Assumptions!$C$138/12 -> 9400 | G12: 50000 | H12: =B12+D12+F12-E12+G12+Balance_Sheet!E11 -> 364333 | I12: =calculation_sheet!N12-operation_exp!H12 -> 17133317 | J12: =J11+I12 -> -56607176
A13: 285000 | B13: 6476 | C13: 144997 | D13: =60000/12 -> 5000 | E13: =Assumptions!E153 -> 7920 | F13: =Assumptions!$C$138/12 -> 9400 | G13: 60000 | H13: =B13+D13+F13-E13+G13+Balance_Sheet!E12 -> 374953 | I13: =calculation_sheet!N13-operation_exp!H13 -> 8920895.6 | J13: =J12+I13-Assumptions!B121 -> -47726280
A14: 285000 | B14: 6476 | C14: 144997 | D14: =60000/12 -> 5000 | E14: =Assumptions!$F$169 -> 20920 | F14: =Assumptions!$C$138/12 -> 9400 | G14: 60000 | H14: =B14+D14+F14-E14+G14+Balance_Sheet!E13 -> 493953 | I14: =calculation_sheet!N14-operation_exp!H14 -> 12526262 | J14: =J13+I14 -> -35200018
A15: 285000 | B15: 6476 | C15: 144997 | D15: =60000/12 -> 5000 | E15: =Assumptions!$F$169 -> 20920 | F15: =Assumptions!$C$138/12+Assumptions!$F$139/12 -> 16825 | G15: 60000 | H15: =B15+D15+F15-E15+G15+Balance_Sheet!E14 -> 501378 | I15: =calculation_sheet!N15-operation_exp!H15 -> 7239288.6 | J15: =J14+I15 -> -27960729
A16: 285000 | B16: =6476*2 -> 12952 | C16: =144997*1.4 -> 202995.8 | D16: =60000/12 -> 5000 | E16: =Assumptions!$F$169 -> 20920 | F16: =Assumptions!$C$138/12+Assumptions!$F$139/12 -> 16825 | G16: 60000 | H16: =B16+D16+F16-E16+G16+Balance_Sheet!E15 -> 507854 | I16: =calculation_sheet!N16-operation_exp!H16 -> 9628638.4 | J16: =J15+I16 -> -18332091
A17: 285000 | B17: =6476*2 -> 12952 | C17: =144997*1.4 -> 202995.8 | D17: =60000/12 -> 5000 | E17: =Assumptions!$F$169 -> 20920 | F17: =Assumptions!$C$138/12+Assumptions!$F$139/12 -> 16825 | G17: 80000 | H17: =B17+D17+F17-E17+G17+Balance_Sheet!E16 -> 585852.8 | I17: =calculation_sheet!N17-operation_exp!H17 -> -5078022.2 | J17: =J16+I17 -> -23410113
A18: 285000 | B18: =6476*2 -> 12952 | C18: =144997*1.4 -> 202995.8 | D18: =60000/12 -> 5000 | E18: =Assumptions!$F$169 -> 20920 | F18: =Assumptions!$C$138/12+Assumptions!$F$139/12 -> 16825 | G18: 80000 | H18: =B18+D18+F18-E18+G18+Balance_Sheet!E17 -> 585852.8 | I18: =calculation_sheet!N18-operation_exp!H18 -> -8483356.1 | J18: =J17+I18 -> -31893469
A19: 285000 | B19: =6476*2 -> 12952 | C19: =144997*1.4 -> 202995.8 | D19: =60000/12 -> 5000 | E19: =Assumptions!$F$169 -> 20920 | F19: =Assumptions!$C$138/12+Assumptions!$F$139/12 -> 16825 | G19: 80000 | H19: =B19+D19+F19-E19+G19+Balance_Sheet!E18 -> 585852.8 | I19: =calculation_sheet!N19-operation_exp!H19 -> -16740541 | J19: =J18+I19 -> -48634011
A20: 285000 | B20: =6476*2 -> 12952 | C20: =144997*1.4 -> 202995.8 | D20: =60000/12 -> 5000 | E20: =Assumptions!$F$169 -> 20920 | F20: =Assumptions!$C$138/12+Assumptions!$F$139/12 -> 16825 | G20: 80000 | H20: =B20+D20+F20-E20+G20+Balance_Sheet!E19 -> 585852.8 | I20: =calculation_sheet!N20-operation_exp!H20 -> -18027602 | J20: =J19+I20 -> -66661612
A21: 285000 | B21: =6476*2 -> 12952 | C21: =144997*1.4 -> 202995.8 | D21: =60000/12 -> 5000 | E21: =Assumptions!$F$169 -> 20920 | F21: =Assumptions!$C$138/12+Assumptions!$F$139/12 -> 16825 | G21: 80000 | H21: =B21+D21+F21-E21+G21+Balance_Sheet!E20 -> 585852.8 | I21: =calculation_sheet!N21-operation_exp!H21 -> -17726340 | J21: =J20+I21 -> -84387952
A22: 285000 | B22: =6476*2 -> 12952 | C22: =144997*1.4 -> 202995.8 | D22: =60000/12 -> 5000 | E22: =Assumptions!$F$169 -> 20920 | F22: =Assumptions!$C$138/12+Assumptions!$F$139/12 -> 16825 | G22: 80000 | H22: =B22+D22+F22-E22+G22+Balance_Sheet!E21 -> 585852.8 | I22: =calculation_sheet!N22-operation_exp!H22 -> -10480979 | J22: =J21+I22 -> -94868931
A23: 285000 | B23: =6476*2 -> 12952 | C23: =144997*1.4 -> 202995.8 | D23: =60000/12 -> 5000 | E23: =Assumptions!$F$169 -> 20920 | F23: =Assumptions!$C$138/12+Assumptions!$F$139/12 -> 16825 | G23: 80000 | H23: =B23+D23+F23-E23+G23+Balance_Sheet!E22 -> 585852.8 | I23: =calculation_sheet!N23-operation_exp!H23 -> 1330733.7 | J23: =J22+I23 -> -93538197
A24: 285000 | B24: =6476*2 -> 12952 | C24: =144997*1.4 -> 202995.8 | D24: =60000/12 -> 5000 | E24: =Assumptions!$F$169 -> 20920 | F24: =Assumptions!$C$138/12+Assumptions!$F$139/12 -> 16825 | G24: 80000 | H24: =B24+D24+F24-E24+G24+Balance_Sheet!E23 -> 585852.8 | I24: =calculation_sheet!N24-operation_exp!H24 -> 16340762 | J24: =J23+I24 -> -77197436
A25: 285000 | B25: =6476*2 -> 12952 | C25: =144997*1.4 -> 202995.8 | D25: =60000/12 -> 5000 | E25: =Assumptions!$F$169 -> 20920 | F25: =Assumptions!$C$138/12+Assumptions!$F$139/12 -> 16825 | G25: 80000 | H25: =B25+D25+F25-E25+G25+Balance_Sheet!E24 -> 585852.8 | I25: =calculation_sheet!N25-operation_exp!H25 -> 7954495.8 | J25: =J24+I25 -> -69242940
A26: 285000 | B26: =6476*2 -> 12952 | C26: =144997*1.4 -> 202995.8 | D26: =60000/12 -> 5000 | E26: =Assumptions!$F$169 -> 20920 | F26: =Assumptions!$C$138/12+Assumptions!$F$139/12 -> 16825 | G26: 100000 | H26: =B26+D26+F26-E26+G26+Balance_Sheet!E25 -> 605852.8 | I26: =calculation_sheet!N26-operation_exp!H26 -> 21637226 | J26: =J25+I26 -> -47605714
A27: 285000 | B27: =6476*2 -> 12952 | C27: =144997*1.4 -> 202995.8 | D27: =60000/12 -> 5000 | E27: =Assumptions!$F$169 -> 20920 | F27: =Assumptions!$C$138/12+Assumptions!$F$139/12 -> 16825 | G27: 100000 | H27: =B27+D27+F27-E27+G27+Balance_Sheet!E26 -> 605852.8 | I27: =calculation_sheet!N27-operation_exp!H27 -> 18651507 | J27: =J26+I27 -> -28954207
... A34: 285000 | B34: =6476*2 -> 12952 | C34: =144997*1.4 -> 202995.8 | D34: =60000/12 -> 5000 | E34: =Assumptions!$F$169 -> 20920 | F34: =Assumptions!$C$138/12+Assumptions!$F$139/12 -> 16825 | G34: 100000 | H34: =B34+D34+F34-E34+G34+Balance_Sheet!E33 -> 605852.8 | I34: =calculation_sheet!N34-operation_exp!H34 -> 142097.47 | J34: =J33+I34 -> 24776476

Sheet final_phase1_full_costs
A1: House_ID | B1: Market | C1: Phase | D1: Tier | E1: Buy_Month | F1: Sell_Month | G1: Holding_Period | H1: Buy_Price | I1: Rehab_Cost | J1: Appreciation_Gain | K1: Uplift_Gain | L1: Sell_Price | M1: Insurance_Cost | N1: Property_Tax_Cost | O1: Maintenance_Cost | P1: HOA_Cost | Q1: Total_Holding_Cost | R1: Buy_Txn_Cost | S1: Sell_Txn_Cost | T1: Service_Fee_Buy | U1: Service_Fee_Sell | V1: Profit
A2: 1 | B2: Dallas | C2: 1 | D2: Tier 1 | E2: 1 | F2: 5 | G2: 4 | H2: 338000 | I2: 27040 | J2: 4447.8785 | K2: 27040 | L2: 396527.88 | M2: 450.66667 | N2: 2028 | O2: 240 | P2: 200 | Q2: 2918.6667 | R2: 3380 | S2: 4758.3345 | T2: 10140 | U2: 11895.836 | V2: =L2-H2 -> 58527.878
A3: 4 | B3: Dallas | C3: 1 | D3: Tier 1 | E3: 1 | F3: 5 | G3: 4 | H3: 338000 | I3: 27040 | J3: 4447.8785 | K3: 27040 | L3: 396527.88 | M3: 450.66667 | N3: 2028 | O3: 240 | P3: 200 | Q3: 2918.6667 | R3: 3380 | S3: 4758.3345 | T3: 10140 | U3: 11895.836 | V3: =L3-H3 -> 58527.878 | Z3: Months | AA3: total price
V4: =SUM(V2:V3) -> 117055.76 | Z4: 5 | AA4: =SUMIF(F2:F314,Z4,H2:H314) -> 676000
A5: 2 | B5: Dallas | C5: 1 | D5: Tier 1 | E5: 1 | F5: 6 | G5: 5 | H5: 338000 | I5: 27040 | J5: 5568.9637 | K5: 27040 | L5: 397648.96 | M5: 563.33333 | N5: 2535 | O5: 300 | P5: 250 | Q5: 3648.3333 | R5: 3380 | S5: 4771.7876 | T5: 10140 | U5: 11929.469 | V5: =L5-H5 -> 59648.964 | Z5: 6 | AA5: =SUMIF(F3:F315,Z5,H3:H315) -> 4138000
A6: 3 | B6: Dallas | C6: 1 | D6: Tier 1 | E6: 1 | F6: 6 | G6: 5 | H6: 338000 | I6: 27040 | J6: 5568.9637 | K6: 27040 | L6: 397648.96 | M6: 563.33333 | N6: 2535 | O6: 300 | P6: 250 | Q6: 3648.3333 | R6: 3380 | S6: 4771.7876 | T6: 10140 | U6: 11929.469 | V6: =L6-H6 -> 59648.964 | Z6: 7 | AA6: =SUMIF(F4:F316,Z6,H4:H316) -> 6481000
A7: 6 | B7: Dallas | C7: 1 | D7: Tier 2 | E7: 1 | F7: 6 | G7: 5 | H7: 443000 | I7: 26580 | J7: 8199.7468 | K7: 26580 | L7: 504359.75 | M7: 738.33333 | N7: 3322.5 | O7: 300 | P7: 250 | Q7: 4610.8333 | R7: 4430 | S7: 6052.317 | T7: 13290 | U7: 15130.792 | V7: =L7-H7 -> 61359.747 | Z7: 8 | AA7: =SUMIF(F5:F317,Z7,H5:H317) -> 11971000
A8: 7 | B8: Dallas | C8: 1 | D8: Tier 2 | E8: 1 | F8: 6 | G8: 5 | H8: 443000 | I8: 26580 | J8: 8199.7468 | K8: 26580 | L8: 504359.75 | M8: 738.33333 | N8: 3322.5 | O8: 300 | P8: 250 | Q8: 4610.8333 | R8: 4430 | S8: 6052.317 | T8: 13290 | U8: 15130.792 | V8: =L8-H8 -> 61359.747 | Z8: 9 | AA8: =SUMIF(F6:F318,Z8,H6:H318) -> 11272000
A9: 8 | B9: Dallas | C9: 1 | D9: Tier 2 | E9: 1 | F9: 6 | G9: 5 | H9: 443000 | I9: 26580 | J9: 8199.7468 | K9: 26580 | L9: 504359.75 | M9: 738.33333 | N9: 3322.5 | O9: 300 | P9: 250 | Q9: 4610.8333 | R9: 4430 | S9: 6052.317 | T9: 13290 | U9: 15130.792 | V9: =L9-H9 -> 61359.747 | Z9: 10 | AA9: =SUMIF(F7:F319,Z9,H7:H319) -> 12414000
A10: 9 | B10: Dallas | C10: 1 | D10: Tier 2 | E10: 1 | F10: 6 | G10: 5 | H10: 443000 | I10: 26580 | J10: 8199.7468 | K10: 26580 | L10: 504359.75 | M10: 738.33333 | N10: 3322.5 | O10: 300 | P10: 250 | Q10: 4610.8333 | R10: 4430 | S10: 6052.317 | T10: 13290 | U10: 15130.792 | V10: =L10-H10 -> 61359.747 | Z10: =Z9+1 -> 11 | AA10: =SUMIF(F8:F320,Z10,H8:H320) -> 20726000
A11: 11 | B11: Dallas | C11: 1 | D11: Tier 1 | E11: 2 | F11: 6 | G11: 4 | H11: 338000 | I11: 27040 | J11: 4447.8785 | K11: 27040 | L11: 396527.88 | M11: 450.66667 | N11: 2028 | O11: 240 | P11: 200 | Q11: 2918.6667 | R11: 3380 | S11: 4758.3345 | T11: 10140 | U11: 11895.836 | V11: =L11-H11 -> 58527.878 | Z11: =Z10+1 -> 12 | AA11: =SUMIF(F9:F321,Z11,H9:H321) -> 11738000
A12: 13 | B12: Dallas | C12: 1 | D12: Tier 1 | E12: 2 | F12: 6 | G12: 4 | H12: 338000 | I12: 27040 | J12: 4447.8785 | K12: 27040 | L12: 396527.88 | M12: 450.66667 | N12: 2028 | O12: 240 | P12: 200 | Q12: 2918.6667 | R12: 3380 | S12: 4758.3345 | T12: 10140 | U12: 11895.836 | V12: =L12-H12 -> 58527.878 | Z12: =Z11+1 -> 13 | AA12: =SUMIF(F10:F322,Z12,H10:H322) -> 13848000
A13: 15 | B13: Dallas | C13: 1 | D13: Tier 1 | E13: 2 | F13: 6 | G13: 4 | H13: 338000 | I13: 27040 | J13: 4447.8785 | K13: 27040 | L13: 396527.88 | M13: 450.66667 | N13: 2028 | O13: 240 | P13: 200 | Q13: 2918.6667 | R13: 3380 | S13: 4758.3345 | T13: 10140 | U13: 11895.836 | V13: =L13-H13 -> 58527.878 | Z13: =Z12+1 -> 14 | AA13: =SUMIF(F11:F323,Z13,H11:H323) -> 10281000
A14: 28 | B14: Dallas | C14: 1 | D14: Tier 1 | E14: 3 | F14: 6 | G14: 3 | H14: 338000 | I14: 27040 | J14: 3330.4514 | K14: 27040 | L14: 395410.45 | M14: 338 | N14: 1521 | O14: 180 | P14: 150 | Q14: 2189 | R14: 3380 | S14: 4744.9254 | T14: 10140 | U14: 11862.314 | V14: =L14-H14 -> 57410.451 | Z14: =Z13+1 -> 15 | AA14: =SUMIF(F12:F324,Z14,H12:H324) -> 13615000
A15: 31 | B15: Dallas | C15: 1 | D15: Tier 1 | E15: 3 | F15: 6 | G15: 3 | H15: 338000 | I15: 27040 | J15: 3330.4514 | K15: 27040 | L15: 395410.45 | M15: 338 | N15: 1521 | O15: 180 | P15: 150 | Q15: 2189 | R15: 3380 | S15: 4744.9254 | T15: 10140 | U15: 11862.314 | V15: =L15-H15 -> 57410.451 | Z15: =Z14+1 -> 16 | AA15: =SUMIF(F13:F325,Z15,H13:H325) -> 6924000
V16: =SUM(V5:V15) -> 655141.45 | Z16: =Z15+1 -> 17 | AA16: =SUMIF(F14:F326,Z16,H14:H326)+SUM(final_phase2_full_costs!H2:H3) -> 6143000
A17: 5 | B17: Dallas | C17: 1 | D17: Tier 2 | E17: 1 | F17: 7 | G17: 6 | H17: 443000 | I17: 26580 | J17: 9857.8199 | K17: 26580 | L17: 506017.82 | M17: 886 | N17: 3987 | O17: 360 | P17: 300 | Q17: 5533 | R17: 4430 | S17: 6072.2138 | T17: 13290 | U17: 15180.535 | V17: =L17-H17 -> 63017.82 | Z17: =Z16+1 -> 18 | AA17: =SUMIF(F15:F327,Z17,H15:H327)+SUM(final_phase2_full_costs!H5:H11) -> 4919000
A18: 10 | B18: Dallas | C18: 1 | D18: Tier 3 | E18: 1 | F18: 7 | G18: 6 | H18: 676000 | I18: 33800 | J18: 16693.872 | K18: 33800 | L18: 760293.87 | M18: 1352 | N18: 6084 | O18: 360 | P18: 300 | Q18: 8096 | R18: 6760 | S18: 9123.5265 | T18: 20280 | U18: 22808.816 | V18: =L18-H18 -> 84293.872 | Z18: =Z17+1 -> 19 | AA18: =SUMIF(final_phase2_full_costs!F2:F397,Z18,final_phase2_full_costs!H2:H397) -> 5024000
A19: 12 | B19: Dallas | C19: 1 | D19: Tier 1 | E19: 2 | F19: 7 | G19: 5 | H19: 338000 | I19: 27040 | J19: 5568.9637 | K19: 27040 | L19: 397648.96 | M19: 563.33333 | N19: 2535 | O19: 300 | P19: 250 | Q19: 3648.3333 | R19: 3380 | S19: 4771.7876 | T19: 10140 | U19: 11929.469 | V19: =L19-H19 -> 59648.964 | Z19: =Z18+1 -> 20 | AA19: =SUMIF(final_phase2_full_costs!F3:F398,Z19,final_phase2_full_costs!H3:H398) -> 4581000
A20: 14 | B20: Dallas | C20: 1 | D20: Tier 1 | E20: 2 | F20: 7 | G20: 5 | H20: 338000 | I20: 27040 | J20: 5568.9637 | K20: 27040 | L20: 397648.96 | M20: 563.33333 | N20: 2535 | O20: 300 | P20: 250 | Q20: 3648.3333 | R20: 3380 | S20: 4771.7876 | T20: 10140 | U20: 11929.469 | V20: =L20-H20 -> 59648.964 | Z20: =Z19+1 -> 21 | AA20: =SUMIF(final_phase2_full_costs!F4:F399,Z20,final_phase2_full_costs!H4:H399) -> 9497000
A21: 16 | B21: Dallas | C21: 1 | D21: Tier 2 | E21: 2 | F21: 7 | G21: 5 | H21: 443000 | I21: 26580 | J21: 8199.7468 | K21: 26580 | L21: 504359.75 | M21: 738.33333 | N21: 3322.5 | O21: 300 | P21: 250 | Q21: 4610.8333 | R21: 4430 | S21: 6052.317 | T21: 13290 | U21: 15130.792 | V21: =L21-H21 -> 61359.747 | Z21: =Z20+1 -> 22 | AA21: =SUMIF(final_phase2_full_costs!F5:F400,Z21,final_phase2_full_costs!H5:H400) -> 13864000
A22: 21 | B22: Dallas | C22: 1 | D22: Tier 2 | E22: 2 | F22: 7 | G22: 5 | H22: 443000 | I22: 26580 | J22: 8199.7468 | K22: 26580 | L22: 504359.75 | M22: 738.33333 | N22: 3322.5 | O22: 300 | P22: 250 | Q22: 4610.8333 | R22: 4430 | S22: 6052.317 | T22: 13290 | U22: 15130.792 | V22: =L22-H22 -> 61359.747 | Z22: =Z21+1 -> 23 | AA22: =SUMIF(final_phase2_full_costs!F6:F401,Z22,final_phase2_full_costs!H6:H401) -> 22828000
A23: 23 | B23: Dallas | C23: 1 | D23: Tier 2 | E23: 2 | F23: 7 | G23: 5 | H23: 443000 | I23: 26580 | J23: 8199.7468 | K23: 26580 | L23: 504359.75 | M23: 738.33333 | N23: 3322.5 | O23: 300 | P23: 250 | Q23: 4610.8333 | R23: 4430 | S23: 6052.317 | T23: 13290 | U23: 15130.792 | V23: =L23-H23 -> 61359.747 | Z23: =Z22+1 -> 24 | AA23: =SUMIF(final_phase2_full_costs!F7:F402,Z23,final_phase2_full_costs!H7:H402) -> 13905000
A24: 29 | B24: Dallas | C24: 1 | D24: Tier 1 | E24: 3 | F24: 7 | G24: 4 | H24: 338000 | I24: 27040 | J24: 4447.8785 | K24: 27040 | L24: 396527.88 | M24: 450.66667 | N24: 2028 | O24: 240 | P24: 200 | Q24: 2918.6667 | R24: 3380 | S24: 4758.3345 | T24: 10140 | U24: 11895.836 | V24: =L24-H24 -> 58527.878 | Z24: =Z23+1 -> 25 | AA24: =SUMIF(final_phase2_full_costs!F8:F403,Z24,final_phase2_full_costs!H8:H403) -> 18627000
A25: 32 | B25: Dallas | C25: 1 | D25: Tier 1 | E25: 3 | F25: 7 | G25: 4 | H25: 338000 | I25: 27040 | J25: 4447.8785 | K25: 27040 | L25: 396527.88 | M25: 450.66667 | N25: 2028 | O25: 240 | P25: 200 | Q25: 2918.6667 | R25: 3380 | S25: 4758.3345 | T25: 10140 | U25: 11895.836 | V25: =L25-H25 -> 58527.878 | Z25: =Z24+1 -> 26 | AA25: =SUMIF(final_phase2_full_costs!F9:F404,Z25,final_phase2_full_costs!H9:H404) -> 16004000
A26: 36 | B26: Dallas | C26: 1 | D26: Tier 2 | E26: 3 | F26: 7 | G26: 4 | H26: 443000 | I26: 26580 | J26: 6547.7445 | K26: 26580 | L26: 502707.74 | M26: 590.66667 | N26: 2658 | O26: 240 | P26: 200 | Q26: 3688.6667 | R26: 4430 | S26: 6032.4929 | T26: 13290 | U26: 15081.232 | V26: =L26-H26 -> 59707.745 | Z26: =Z25+1 -> 27 | AA26: =SUMIF(final_phase2_full_costs!F10:F405,Z26,final_phase2_full_costs!H10:H405) -> 14402000
A27: 39 | B27: Dallas | C27: 1 | D27: Tier 2 | E27: 3 | F27: 7 | G27: 4 | H27: 443000 | I27: 26580 | J27: 6547.7445 | K27: 26580 | L27: 502707.74 | M27: 590.66667 | N27: 2658 | O27: 240 | P27: 200 | Q27: 3688.6667 | R27: 4430 | S27: 6032.4929 | T27: 13290 | U27: 15081.232 | V27: =L27-H27 -> 59707.745 | Z27: =Z26+1 -> 28 | AA27: =SUMIF(final_phase2_full_costs!F11:F406,Z27,final_phase2_full_costs!H11:H406) -> 15059000
A28: 42 | B28: Dallas | C28: 1 | D28: Tier 2 | E28: 3 | F28: 7 | G28: 4 | H28: 443000 | I28: 26580 | J28: 6547.7445 | K28: 26580 | L28: 502707.74 | M28: 590.66667 | N28: 2658 | O28: 240 | P28: 200 | Q28: 3688.6667 | R28: 4430 | S28: 6032.4929 | T28: 13290 | U28: 15081.232 | V28: =L28-H28 -> 59707.745 | Z28: =Z27+1 -> 29 | AA28: =SUMIF(final_phase2_full_costs!F12:F407,Z28,final_phase2_full_costs!H12:H407) -> 8611000
A29: 47 | B29: Dallas | C29: 1 | D29: Tier 1 | E29: 4 | F29: 7 | G29: 3 | H29: 338000 | I29: 27040 | J29: 3330.4514 | K29: 27040 | L29: 395410.45 | M29: 338 | N29: 1521 | O29: 180 | P29: 150 | Q29: 2189 | R29: 3380 | S29: 4744.9254 | T29: 10140 | U29: 11862.314 | V29: =L29-H29 -> 57410.451 | Z29: =Z28+1 -> 30 | AA29: =SUMIF(final_phase2_full_costs!F13:F408,Z29,final_phase2_full_costs!H13:H408) -> 6830000
... A32: 53 | B32: Dallas | C32: 1 | D32: Tier 1 | E32: 4 | F32: 7 | G32: 3 | H32: 338000 | I32: 27040 | J32: 3330.4514 | K32: 27040 | L32: 395410.45 | M32: 338 | N32: 1521 | O32: 180 | P32: 150 | Q32: 2189 | R32: 3380 | S32: 4744.9254 | T32: 10140 | U32: 11862.314 | V32: =L32-H32 -> 57410.451 | Z32: =Z31+1 -> 33 | AA32: =SUMIF(final_phase2_full_costs!F16:F411,Z32,final_phase2_full_costs!H16:H411) -> 630000
V33: =SUM(V17:V32) -> 976509.66 | Z33: =Z32+1 -> 34 | AA33: =SUMIF(final_phase2_full_costs!F17:F412,Z33,final_phase2_full_costs!H17:H412) -> 0
A34: 17 | B34: Dallas | C34: 1 | D34: Tier 2 | E34: 2 | F34: 8 | G34: 6 | H34: 443000 | I34: 26580 | J34: 9857.8199 | K34: 26580 | L34: 506017.82 | M34: 886 | N34: 3987 | O34: 360 | P34: 300 | Q34: 5533 | R34: 4430 | S34: 6072.2138 | T34: 13290 | U34: 15180.535 | V34: =L34-H34 -> 63017.82 | Z34: =Z33+1 -> 35 | AA34: =SUMIF(final_phase2_full_costs!F18:F413,Z34,final_phase2_full_costs!H18:H413) -> 0
A35: 18 | B35: Dallas | C35: 1 | D35: Tier 2 | E35: 2 | F35: 8 | G35: 6 | H35: 443000 | I35: 26580 | J35: 9857.8199 | K35: 26580 | L35: 506017.82 | M35: 886 | N35: 3987 | O35: 360 | P35: 300 | Q35: 5533 | R35: 4430 | S35: 6072.2138 | T35: 13290 | U35: 15180.535 | V35: =L35-H35 -> 63017.82
A36: 19 | B36: Dallas | C36: 1 | D36: Tier 2 | E36: 2 | F36: 8 | G36: 6 | H36: 443000 | I36: 26580 | J36: 9857.8199 | K36: 26580 | L36: 506017.82 | M36: 886 | N36: 3987 | O36: 360 | P36: 300 | Q36: 5533 | R36: 4430 | S36: 6072.2138 | T36: 13290 | U36: 15180.535 | V36: =L36-H36 -> 63017.82
A37: 20 | B37: Dallas | C37: 1 | D37: Tier 2 | E37: 2 | F37: 8 | G37: 6 | H37: 443000 | I37: 26580 | J37: 9857.8199 | K37: 26580 | L37: 506017.82 | M37: 886 | N37: 3987 | O37: 360 | P37: 300 | Q37: 5533 | R37: 4430 | S37: 6072.2138 | T37: 13290 | U37: 15180.535 | V37: =L37-H37 -> 63017.82
A38: 22 | B38: Dallas | C38: 1 | D38: Tier 2 | E38: 2 | F38: 8 | G38: 6 | H38: 443000 | I38: 26580 | J38: 9857.8199 | K38: 26580 | L38: 506017.82 | M38: 886 | N38: 3987 | O38: 360 | P38: 300 | Q38: 5533 | R38: 4430 | S38: 6072.2138 | T38: 13290 | U38: 15180.535 | V38: =L38-H38 -> 63017.82
A39: 24 | B39: Dallas | C39: 1 | D39: Tier 3 | E39: 2 | F39: 8 | G39: 6 | H39: 676000 | I39: 33800 | J39: 16693.872 | K39: 33800 | L39: 760293.87 | M39: 1352 | N39: 6084 | O39: 360 | P39: 300 | Q39: 8096 | R39: 6760 | S39: 9123.5265 | T39: 20280 | U39: 22808.816 | V39: =L39-H39 -> 84293.872
A40: 25 | B40: Dallas | C40: 1 | D40: Tier 3 | E40: 2 | F40: 8 | G40: 6 | H40: 676000 | I40: 33800 | J40: 16693.872 | K40: 33800 | L40: 760293.87 | M40: 1352 | N40: 6084 | O40: 360 | P40: 300 | Q40: 8096 | R40: 6760 | S40: 9123.5265 | T40: 20280 | U40: 22808.816 | V40: =L40-H40 -> 84293.872
A41: 26 | B41: Dallas | C41: 1 | D41: Tier 1 | E41: 3 | F41: 8 | G41: 5 | H41: 338000 | I41: 27040 | J41: 5568.9637 | K41: 27040 | L41: 397648.96 | M41: 563.33333 | N41: 2535 | O41: 300 | P41: 250 | Q41: 3648.3333 | R41: 3380 | S41: 4771.7876 | T41: 10140 | U41: 11929.469 | V41: =L41-H41 -> 59648.964
A42: 27 | B42: Dallas | C42: 1 | D42: Tier 1 | E42: 3 | F42: 8 | G42: 5 | H42: 338000 | I42: 27040 | J42: 5568.9637 | K42: 27040 | L42: 397648.96 | M42: 563.33333 | N42: 2535 | O42: 300 | P42: 250 | Q42: 3648.3333 | R42: 3380 | S42: 4771.7876 | T42: 10140 | U42: 11929.469 | V42: =L42-H42 -> 59648.964
...

Sheet Balance_Sheet
A1: Line Item | B1: Cash | C1: Inventory Value | D1: Total Assets | E1: Liabilities | F1: Equity
A2: Jan | B2: =Assumptions!B4+operation_exp!J2 -> 4.9541108e+08 | C2: =calculation_sheet!G2 -> 4243000 | D2: =B2+C2 -> 4.9965408e+08 | E2: =operation_exp!C2+operation_exp!A2+Assumptions!$C$17 -> 301997 | F2: =D2-E2 -> 4.9935208e+08
A3: Feb | B3: =Assumptions!$B$4+operation_exp!J3 -> 488243639 | C3: =C2+calculation_sheet!G3 -> 10829000 | D3: =B3+C3 -> 499072639 | E3: =operation_exp!C3+operation_exp!A3+Assumptions!$C$17 -> 301997 | F3: =D3-E3 -> 498770642
A4: Mar | B4: =Assumptions!$B$4+operation_exp!J4 -> 4.7874649e+08 | C4: =C3+calculation_sheet!G4 -> 19653000 | D4: =B4+C4 -> 4.9839949e+08 | E4: =operation_exp!C4+operation_exp!A4+Assumptions!$C$17 -> 301997 | F4: =D4-E4 -> 4.9809749e+08
A5: Apr | B5: =Assumptions!$B$4+operation_exp!J5 -> 4.6690016e+08 | C5: =C4+calculation_sheet!G5 -> 30715000 | D5: =B5+C5 -> 4.9761516e+08 | E5: =operation_exp!C5+operation_exp!A5+Assumptions!$C$17 -> 301997 | F5: =D5-E5 -> 4.9731316e+08
A6: May | B6: =Assumptions!$B$4+operation_exp!J6 -> 4.51349e+08 | C6: =C5+calculation_sheet!G6-final_phase1_full_costs!AA4 -> 45449000 | D6: =B6+C6 -> 4.96798e+08 | E6: =operation_exp!C6+operation_exp!A6+Assumptions!$C$17 -> 301997 | F6: =D6-E6 -> 4.9649601e+08
A7: Jun | B7: =Assumptions!$B$4+operation_exp!J7 -> 4.3757905e+08 | C7: =C6+calculation_sheet!G7-final_phase1_full_costs!AA5 -> 58959000 | D7: =B7+C7 -> 4.9653805e+08 | E7: =operation_exp!C7+operation_exp!A7+Assumptions!$C$17 -> 301997 | F7: =D7-E7 -> 4.9623606e+08
A8: Jul | B8: =Assumptions!$B$4+operation_exp!J8 -> 4.2653123e+08 | C8: =C7+calculation_sheet!G8-final_phase1_full_costs!AA6 -> 70126000 | D8: =B8+C8 -> 4.9665723e+08 | E8: =operation_exp!C8+operation_exp!A8+Assumptions!$C$17 -> 301997 | F8: =D8-E8 -> 4.9635523e+08
A9: Aug | B9: =Assumptions!$B$4+operation_exp!J9 -> 4.2420836e+08 | C9: =C8+calculation_sheet!G9-final_phase1_full_costs!AA7 -> 73565000 | D9: =B9+C9 -> 4.9777336e+08 | E9: =operation_exp!C9+operation_exp!A9+Assumptions!$C$17 -> 301997 | F9: =D9-E9 -> 4.9747136e+08
A10: Sep | B10: =Assumptions!$B$4+operation_exp!J10 -> 4.2350045e+08 | C10: =C9+calculation_sheet!G10-final_phase1_full_costs!AA8 -> 75360000 | D10: =B10+C10 -> 4.9886045e+08 | E10: =operation_exp!C10+operation_exp!A10+Assumptions!$C$17 -> 301997 | F10: =D10-E10 -> 4.9855845e+08
A11: Oct | B11: =Assumptions!$B$4+operation_exp!J11 -> 4.2625951e+08 | C11: =C10+calculation_sheet!G11-final_phase1_full_costs!AA9 -> 74008000 | D11: =B11+C11 -> 5.0026751e+08 | E11: =operation_exp!C11+operation_exp!A11+Assumptions!$C$17 -> 301997 | F11: =D11-E11 -> 4.9996551e+08
A12: Nov | B12: =Assumptions!$B$4+operation_exp!J12 -> 4.4339282e+08 | C12: =C11+calculation_sheet!G12-final_phase1_full_costs!AA10 -> 59868000 | D12: =B12+C12 -> 5.0326082e+08 | E12: =operation_exp!C12+operation_exp!A12+Assumptions!$C$17 -> 301997 | F12: =D12-E12 -> 5.0295883e+08
A13: Dec | B13: =Assumptions!$B$4+operation_exp!J13 -> 4.5227372e+08 | C13: =C12+calculation_sheet!G13-final_phase1_full_costs!AA11 -> 52373000 | D13: =B13+C13 -> 5.0464672e+08 | E13: =operation_exp!C13+operation_exp!A13+Assumptions!$C$17 -> 433997 | F13: =D13-E13 -> 5.0421272e+08
A14: Jan | B14: =Assumptions!$B$4+operation_exp!J14 -> 4.6479998e+08 | C14: =C13+calculation_sheet!G14-final_phase1_full_costs!AA12 -> 41649000 | D14: =B14+C14 -> 5.0644898e+08 | E14: =operation_exp!C14+operation_exp!A14+Assumptions!$C$17 -> 433997 | F14: =D14-E14 -> 5.0601498e+08
A15: Feb | B15: =Assumptions!$B$4+operation_exp!J15 -> 4.7203927e+08 | C15: =C14+calculation_sheet!G15-final_phase1_full_costs!AA13 -> 35611000 | D15: =B15+C15 -> 5.0765027e+08 | E15: =operation_exp!C15+operation_exp!A15+Assumptions!$C$17 -> 433997 | F15: =D15-E15 -> 5.0721627e+08
A16: Mar | B16: =Assumptions!$B$4+operation_exp!J16 -> 4.8166791e+08 | C16: =C15+calculation_sheet!G16-final_phase1_full_costs!AA14 -> 27696000 | D16: =B16+C16 -> 5.0936391e+08 | E16: =operation_exp!C16+operation_exp!A16+Assumptions!$C$17 -> 491995.8 | F16: =D16-E16 -> 5.0887191e+08
A17: Apr | B17: =Assumptions!$B$4+operation_exp!J17 -> 4.7658989e+08 | C17: =C16+calculation_sheet!G17-final_phase1_full_costs!AA15 -> 32857000 | D17: =B17+C17 -> 5.0944689e+08 | E17: =operation_exp!C17+operation_exp!A17+Assumptions!$C$17 -> 491995.8 | F17: =D17-E17 -> 5.0895489e+08
... A33: Aug | B33: =Assumptions!$B$4+operation_exp!J33 -> 5.2463438e+08 | C33: =C32+calculation_sheet!G33-final_phase1_full_costs!AA31 -> 630000 | D33: =B33+C33 -> 5.2526438e+08 | E33: =operation_exp!C33+operation_exp!A33+Assumptions!$C$17 -> 491995.8 | F33: =D33-E33 -> 5.2477238e+08
A34: Sep | B34: =Assumptions!$B$4+operation_exp!J34 -> 5.2477648e+08 | C34: =C33+calculation_sheet!G34-final_phase1_full_costs!AA32 -> 0 | D34: =B34+C34 -> 5.2477648e+08 | E34: 0 | F34: =D34-E34 -> 5.2477648e+08

Sheet Income_Statement
A1: Line Item | B1: Revenue | C1: Cost of Goods Sold (COGS) | D1: Gross Profit | E1: Total_Opex | F1: Net Income
A2: Jan | B2: =calculation_sheet!M2+operation_exp!E2+calculation_sheet!L2 -> 170120 | C2: =calculation_sheet!G2+calculation_sheet!H2+calculation_sheet!I2+calculation_sheet!J2 -> 4569168.8 | D2: =B2-C2 -> -4399048.8 | E2: =operation_exp!H2+operation_exp!E2+Assumptions!B110 -> 189876 | F2: =D2-E2 -> -4588924.8
A3: Feb | B3: =calculation_sheet!M3+operation_exp!E3+calculation_sheet!L3 -> 264340 | C3: =calculation_sheet!G3+calculation_sheet!H3+calculation_sheet!I3+calculation_sheet!J3+calculation_sheet!K3 -> 7089903.2 | D3: =B3-C3 -> -6825563.2 | E3: =operation_exp!H3+operation_exp!E3 -> 341873 | F3: =D3-E3 -> -7167436.2
A4: Mar | B4: =calculation_sheet!M4+operation_exp!E4+calculation_sheet!L4 -> 354420 | C4: =calculation_sheet!G4+calculation_sheet!H4+calculation_sheet!I4+calculation_sheet!J4+calculation_sheet!K4 -> 9509700.5 | D4: =B4-C4 -> -9155280.5 | E4: =operation_exp!H4+operation_exp!E4 -> 341873 | F4: =D4-E4 -> -9497153.5
A5: Apr | B5: =calculation_sheet!M5+operation_exp!E5+calculation_sheet!L5 -> 444700 | C5: =calculation_sheet!G5+calculation_sheet!H5+calculation_sheet!I5+calculation_sheet!J5+calculation_sheet!K5 -> 11934151 | D5: =B5-C5 -> -11489451 | E5: =operation_exp!H5+operation_exp!E5 -> 356873 | F5: =D5-E5 -> -11846324
A6: May | B6: =calculation_sheet!M6+operation_exp!E6+calculation_sheet!L6 -> 1444318 | C6: =calculation_sheet!G6+calculation_sheet!H6+calculation_sheet!I6+calculation_sheet!J6+calculation_sheet!K6 -> 16638604 | D6: =B6-C6 -> -15194286 | E6: =operation_exp!H6+operation_exp!E6 -> 356873 | F6: =D6-E6 -> -15551159
A7: Jun | B7: =calculation_sheet!M7+operation_exp!E7+calculation_sheet!L7 -> 5694907.1 | C7: =calculation_sheet!G7+calculation_sheet!H7+calculation_sheet!I7+calculation_sheet!J7+calculation_sheet!K7 -> 19107983 | D7: =B7-C7 -> -13413076 | E7: =operation_exp!H7+operation_exp!E7 -> 356873 | F7: =D7-E7 -> -13769949
A8: Jul | B8: =calculation_sheet!M8+operation_exp!E8+calculation_sheet!L8 -> 8466790 | C8: =calculation_sheet!G8+calculation_sheet!H8+calculation_sheet!I8+calculation_sheet!J8+calculation_sheet!K8 -> 19157739 | D8: =B8-C8 -> -10690949 | E8: =operation_exp!H8+operation_exp!E8 -> 356873 | F8: =D8-E8 -> -11047822
A9: Aug | B9: =calculation_sheet!M9+operation_exp!E9+calculation_sheet!L9 -> 14874974 | C9: =calculation_sheet!G9+calculation_sheet!H9+calculation_sheet!I9+calculation_sheet!J9+calculation_sheet!K9 -> 16825974 | D9: =B9-C9 -> -1950999.8 | E9: =operation_exp!H9+operation_exp!E9 -> 371873 | F9: =D9-E9 -> -2322872.8
A10: Sep | B10: =calculation_sheet!M10+operation_exp!E10+calculation_sheet!L10 -> 13978823 | C10: =calculation_sheet!G10+calculation_sheet!H10+calculation_sheet!I10+calculation_sheet!J10+calculation_sheet!K10 -> 14314863 | D10: =B10-C10 -> -336039.68 | E10: =operation_exp!H10+operation_exp!E10 -> 371873 | F10: =D10-E10 -> -707912.68
A11: Oct | B11: =calculation_sheet!M11+operation_exp!E11+calculation_sheet!L11 -> 15297341 | C11: =calculation_sheet!G11+calculation_sheet!H11+calculation_sheet!I11+calculation_sheet!J11+calculation_sheet!K11 -> 12166407 | D11: =B11-C11 -> 3130934 | E11: =operation_exp!H11+operation_exp!E11 -> 371873 | F11: =D11-E11 -> 2759061
A12: Nov | B12: =calculation_sheet!M12+operation_exp!E12+calculation_sheet!L12 -> 24933578 | C12: =calculation_sheet!G12+calculation_sheet!H12+calculation_sheet!I12+calculation_sheet!J12+calculation_sheet!K12 -> 7428388.4 | D12: =B12-C12 -> 17505190 | E12: =operation_exp!H12+operation_exp!E12 -> 371873 | F12: =D12-E12 -> 17133317
A13: Dec | B13: =calculation_sheet!M13+operation_exp!E13+calculation_sheet!L13 -> 14106548 | C13: =calculation_sheet!G13+calculation_sheet!H13+calculation_sheet!I13+calculation_sheet!J13+calculation_sheet!K13 -> 4802779 | D13: =B13-C13 -> 9303768.6 | E13: =operation_exp!H13+operation_exp!E13 -> 382873 | F13: =D13-E13 -> 8920895.6
A14: Jan | B14: =calculation_sheet!M14+operation_exp!E14+calculation_sheet!L14 -> 16639409 | C14: =calculation_sheet!G14+calculation_sheet!H14+calculation_sheet!I14+calculation_sheet!J14+calculation_sheet!K14 -> 3598273.6 | D14: =B14-C14 -> 13041135 | E14: =operation_exp!H14+operation_exp!E14 -> 514873 | F14: =D14-E14 -> 12526262
A15: Feb | B15: =calculation_sheet!M15+operation_exp!E15+calculation_sheet!L15 -> 12519928 | C15: =calculation_sheet!G15+calculation_sheet!H15+calculation_sheet!I15+calculation_sheet!J15+calculation_sheet!K15 -> 4758341 | D15: =B15-C15 -> 7761586.6 | E15: =operation_exp!H15+operation_exp!E15 -> 522298 | F15: =D15-E15 -> 7239288.6
A16: Mar | B16: =calculation_sheet!M16+operation_exp!E16+calculation_sheet!L16 -> 16497876 | C16: =calculation_sheet!G16+calculation_sheet!H16+calculation_sheet!I16+calculation_sheet!J16+calculation_sheet!K16 -> 6340463.4 | D16: =B16-C16 -> 10157412 | E16: =operation_exp!H16+operation_exp!E16+Assumptions!B121 -> 568774 | F16: =D16-E16 -> 9588638.4
A17: Apr | B17: =calculation_sheet!M17+operation_exp!E17+calculation_sheet!L17 -> 8749103.8 | C17: =calculation_sheet!G17+calculation_sheet!H17+calculation_sheet!I17+calculation_sheet!J17+calculation_sheet!K17 -> 13220353 | D17: =B17-C17 -> -4471249.4 | E17: =operation_exp!H17+operation_exp!E17 -> 606772.8 | F17: =D17-E17 -> -5078022.2
A18: May | B18: =calculation_sheet!M18+operation_exp!E18+calculation_sheet!L18 -> 7987128.9 | C18: =calculation_sheet!G18+calculation_sheet!H18+calculation_sheet!I18+calculation_sheet!J18+calculation_sheet!K18 -> 15863712 | D18: =B18-C18 -> -7876583.3 | E18: =operation_exp!H18+operation_exp!E18 -> 606772.8 | F18: =D18-E18 -> -8483356.1
A19: Jun | B19: =calculation_sheet!M19+operation_exp!E19+calculation_sheet!L19 -> 6795864.9 | C19: =calculation_sheet!G19+calculation_sheet!H19+calculation_sheet!I19+calculation_sheet!J19+calculation_sheet!K19 -> 22929633 | D19: =B19-C19 -> -16133769 | E19: =operation_exp!H19+operation_exp!E19 -> 606772.8 | F19: =D19-E19 -> -16740541
A20: Jul | B20: =calculation_sheet!M20+operation_exp!E20+calculation_sheet!L20 -> 6994921.9 | C20: =calculation_sheet!G20+calculation_sheet!H20+calculation_sheet!I20+calculation_sheet!J20+calculation_sheet!K20 -> 24415751 | D20: =B20-C20 -> -17420829 | E20: =operation_exp!H20+operation_exp!E20 -> 606772.8 | F20: =D20-E20 -> -18027602
A21: Aug | B21: =calculation_sheet!M21+operation_exp!E21+calculation_sheet!L21 -> 6403262.7 | C21: =calculation_sheet!G21+calculation_sheet!H21+calculation_sheet!I21+calculation_sheet!J21+calculation_sheet!K21 -> 23522830 | D21: =B21-C21 -> -17119567 | E21: =operation_exp!H21+operation_exp!E21 -> 606772.8 | F21: =D21-E21 -> -17726340
A22: Sep | B22: =calculation_sheet!M22+operation_exp!E22+calculation_sheet!L22 -> 12405881 | C22: =calculation_sheet!G22+calculation_sheet!H22+calculation_sheet!I22+calculation_sheet!J22+calculation_sheet!K22 -> 22280087 | D22: =B22-C22 -> -9874205.9 | E22: =operation_exp!H22+operation_exp!E22 -> 606772.8 | F22: =D22-E22 -> -10480979
A23: Oct | B23: =calculation_sheet!M23+operation_exp!E23+calculation_sheet!L23 -> 17317271 | C23: =calculation_sheet!G23+calculation_sheet!H23+calculation_sheet!I23+calculation_sheet!J23+calculation_sheet!K23 -> 15379764 | D23: =B23-C23 -> 1937506.5 | E23: =operation_exp!H23+operation_exp!E23 -> 606772.8 | F23: =D23-E23 -> 1330733.7
A24: Nov | B24: =calculation_sheet!M24+operation_exp!E24+calculation_sheet!L24 -> 28073284 | C24: =calculation_sheet!G24+calculation_sheet!H24+calculation_sheet!I24+calculation_sheet!J24+calculation_sheet!K24 -> 11125750 | D24: =B24-C24 -> 16947534 | E24: =operation_exp!H24+operation_exp!E24 -> 606772.8 | F24: =D24-E24 -> 16340762
A25: Dec | B25: =calculation_sheet!M25+operation_exp!E25+calculation_sheet!L25 -> 17136456 | C25: =calculation_sheet!G25+calculation_sheet!H25+calculation_sheet!I25+calculation_sheet!J25+calculation_sheet!K25 -> 8575187 | D25: =B25-C25 -> 8561268.6 | E25: =operation_exp!H25+operation_exp!E25 -> 606772.8 | F25: =D25-E25 -> 7954495.8
A26: Jan | B26: =calculation_sheet!M26+operation_exp!E26+calculation_sheet!L26 -> 22594460 | C26: =calculation_sheet!G26+calculation_sheet!H26+calculation_sheet!I26+calculation_sheet!J26+calculation_sheet!K26 -> 330461.26 | D26: =B26-C26 -> 22263999 | E26: =operation_exp!H26+operation_exp!E26 -> 626772.8 | F26: =D26-E26 -> 21637226
A27: Feb | B27: =calculation_sheet!M27+operation_exp!E27+calculation_sheet!L27 -> 19550570 | C27: =calculation_sheet!G27+calculation_sheet!H27+calculation_sheet!I27+calculation_sheet!J27+calculation_sheet!K27 -> 272290.1 | D27: =B27-C27 -> 19278280 | E27: =operation_exp!H27+operation_exp!E27 -> 626772.8 | F27: =D27-E27 -> 18651507
A28: Mar | B28: =calculation_sheet!M28+operation_exp!E28+calculation_sheet!L28 -> 17445394 | C28: =calculation_sheet!G28+calculation_sheet!H28+calculation_sheet!I28+calculation_sheet!J28+calculation_sheet!K28 -> 225882.9 | D28: =B28-C28 -> 17219511 | E28: =operation_exp!H28+operation_exp!E28 -> 626772.8 | F28: =D28-E28 -> 16592738
... A34: Sep | B34: =calculation_sheet!M34+operation_exp!E34+calculation_sheet!L34 -> 776114.34 | C34: =calculation_sheet!G34+calculation_sheet!H34+calculation_sheet!I34+calculation_sheet!J34+calculation_sheet!K34 -> 7244.0704 | D34: =B34-C34 -> 768870.27 | E34: =operation_exp!H34+operation_exp!E34 -> 626772.8 | F34: =D34-E34 -> 142097.47
F36: =SUM(F2:F34) -> 24776476

Sheet cash flow
A1: Line Item | B1: Cash Flow from Operating Activities (CFO) | C1: Cash Flow from Investing Activities (CFI) | D1: Net Change in Cash | E1: Beginning Cash | F1: ending cash
A2: Jan | B2: =operation_exp!I2 -> -4438924.8 | C2: -150000 | D2: =B2+C2 -> -4588924.8 | E2: 500000000 | F2: =E2+D2 -> 4.9541108e+08
A3: Feb | B3: =operation_exp!I3 -> -7167436.2 | D3: =B3+C3 -> -7167436.2 | E3: =F2 -> 4.9541108e+08 | F3: =E3+D3 -> 488243639
A4: Mar | B4: =operation_exp!I4 -> -9497153.5 | D4: =B4+C4 -> -9497153.5 | E4: =F3 -> 488243639 | F4: =E4+D4 -> 4.7874649e+08
A5: Apr | B5: =operation_exp!I5 -> -11846324 | D5: =B5+C5 -> -11846324 | E5: =F4 -> 4.7874649e+08 | F5: =E5+D5 -> 4.6690016e+08
A6: May | B6: =operation_exp!I6 -> -15551159 | D6: =B6+C6 -> -15551159 | E6: =F5 -> 4.6690016e+08 | F6: =E6+D6 -> 4.51349e+08
